<?xml version="1.0" ?>
<robot name="(Unsaved)" xmlns:xacro="http://www.ros.org/wiki/xacro">

<xacro:include filename="$(find (Unsaved)_description)/urdf/materials.xacro" />
<xacro:include filename="$(find (Unsaved)_description)/urdf/(Unsaved).trans" />
<xacro:include filename="$(find (Unsaved)_description)/urdf/(Unsaved).gazebo" />
<link name="base_link">
  <inertial>
    <origin xyz="0.016548887214996567 0.0 0.002024539145487377" rpy="0 0 0"/>
    <mass value="1.5224079027739417"/>
    <inertia ixx="0.001364" iyy="0.005616" izz="0.006428" ixy="-0.0" iyz="0.0" ixz="-0.000307"/>
  </inertial>
  <visual>
    <origin xyz="0 0 0" rpy="0 0 0"/>
    <geometry>
      <mesh filename="package://(Unsaved)_description/meshes/base_link.stl" scale="0.001 0.001 0.001"/>
    </geometry>
    <material name="silver"/>
  </visual>
  <collision>
    <origin xyz="0 0 0" rpy="0 0 0"/>
    <geometry>
      <mesh filename="package://(Unsaved)_description/meshes/base_link.stl" scale="0.001 0.001 0.001"/>
    </geometry>
  </collision>
</link>

<link name="left_wheel_1">
  <inertial>
    <origin xyz="0.0 0.0025000000000000022 -3.469446951953614e-18" rpy="0 0 0"/>
    <mass value="0.11097676048805946"/>
    <inertia ixx="2.5e-05" iyy="5e-05" izz="2.5e-05" ixy="0.0" iyz="0.0" ixz="0.0"/>
  </inertial>
  <visual>
    <origin xyz="0.08 -0.055 0.02" rpy="0 0 0"/>
    <geometry>
      <mesh filename="package://(Unsaved)_description/meshes/left_wheel_1.stl" scale="0.001 0.001 0.001"/>
    </geometry>
    <material name="silver"/>
  </visual>
  <collision>
    <origin xyz="0.08 -0.055 0.02" rpy="0 0 0"/>
    <geometry>
      <mesh filename="package://(Unsaved)_description/meshes/left_wheel_1.stl" scale="0.001 0.001 0.001"/>
    </geometry>
  </collision>
</link>

<link name="right_wheel_1">
  <inertial>
    <origin xyz="0.0 -0.0025000000000000022 1.0408340855860843e-17" rpy="0 0 0"/>
    <mass value="0.1109767604880594"/>
    <inertia ixx="2.5e-05" iyy="5e-05" izz="2.5e-05" ixy="0.0" iyz="0.0" ixz="0.0"/>
  </inertial>
  <visual>
    <origin xyz="0.08 0.055 0.02" rpy="0 0 0"/>
    <geometry>
      <mesh filename="package://(Unsaved)_description/meshes/right_wheel_1.stl" scale="0.001 0.001 0.001"/>
    </geometry>
    <material name="silver"/>
  </visual>
  <collision>
    <origin xyz="0.08 0.055 0.02" rpy="0 0 0"/>
    <geometry>
      <mesh filename="package://(Unsaved)_description/meshes/right_wheel_1.stl" scale="0.001 0.001 0.001"/>
    </geometry>
  </collision>
</link>

<link name="lidar_1">
  <inertial>
    <origin xyz="-3.469446951953614e-17 4.825019250101691e-18 0.015" rpy="0 0 0"/>
    <mass value="0.46240316870024756"/>
    <inertia ixx="0.000107" iyy="0.000107" izz="0.000145" ixy="0.0" iyz="0.0" ixz="0.0"/>
  </inertial>
  <visual>
    <origin xyz="-0.055 -0.0 -0.025" rpy="0 0 0"/>
    <geometry>
      <mesh filename="package://(Unsaved)_description/meshes/lidar_1.stl" scale="0.001 0.001 0.001"/>
    </geometry>
    <material name="silver"/>
  </visual>
  <collision>
    <origin xyz="-0.055 -0.0 -0.025" rpy="0 0 0"/>
    <geometry>
      <mesh filename="package://(Unsaved)_description/meshes/lidar_1.stl" scale="0.001 0.001 0.001"/>
    </geometry>
  </collision>
</link>

<joint name="Rev1" type="continuous">
  <origin xyz="-0.08 0.055 -0.02" rpy="0 0 0"/>
  <parent link="base_link"/>
  <child link="left_wheel_1"/>
  <axis xyz="0.0 1.0 0.0"/>
</joint>

<joint name="Rev2" type="continuous">
  <origin xyz="-0.08 -0.055 -0.02" rpy="0 0 0"/>
  <parent link="base_link"/>
  <child link="right_wheel_1"/>
  <axis xyz="0.0 -1.0 0.0"/>
</joint>

<joint name="Rev3" type="continuous">
  <origin xyz="0.055 0.0 0.025" rpy="0 0 0"/>
  <parent link="base_link"/>
  <child link="lidar_1"/>
  <axis xyz="0.0 0.0 1.0"/>
</joint>

</robot>
